Workbook

Sheet README
A1: Anaerobic Digestion of Olive Mill Waste — Project Database
A3: PURPOSE
A4: Formal data repository for the olive mill waste anaerobic digestion modelling
A5: project. Trains ANN, RNN, and LSTM models in PyTorch.
A6: All parameters corrected and validated against published literature limits.
A8: SHEET GUIDE
A9: README | B9: This sheet — parameters, limits, sources
A10: PHYSICAL_LIMITS | B10: Full limits table with live pass/fail check against RAW_SIMULATION
A11: RAW_SIMULATION | B11: 1,080 rows ODE output — out-of-range cells highlighted red
A12: STANDARDISATION_REF | B12: 1,080 rows 8-column format for StandardScaler fitting
A13: PREPARED_TRAINING | B13: 27,000 rows noise-augmented training data for PyTorch
A15: ODE EQUATIONS
A16: dS/dt = -k_h x S x f_T(T) x f_pH(pH)
A17: dM/dt = Y_CH4 x k_h x S x f_T(T) x f_pH(pH)
A18: dpH/dt = -k_pH x max(S - S_ref, 0) x (pH - pH_eq)
A19: f_T(T) = exp(-0.07 x (T - 35))
A20: f_pH(pH) = 1 / (1 + exp(-2 x (pH - 6.5)))
A22: KINETIC PARAMETERS
A23: k_h = 0.08 /day | B23: Hydrolysis rate — Keating et al. (2016) PMC4875066
A24: Y_CH4 = 380 mL CH4/g VS | B24: Methane yield — Federici et al. (2020) J. Applied Phycology
A25: k_pH = 0.003 | B25: Acidification rate — self-limiting form, calibrated to pH 6.8-7.4
A26: S_ref = 2.0 g VS/L | B26: Residual non-degradable VS fraction
A27: pH_eq = 6.8 | B27: Bicarbonate buffer floor — Borja (2003); ADM1 (Batstone 2002)
A28: T_opt = 35 °C | B28: Mesophilic optimum — Borja et al. (2003)
A30: PHYSICAL LIMITS SUMMARY
A31: S : 0 to 55 g VS/L | B31: S>=0 physical; S0_max=55 (Borja 2003)
A32: M : 0 to 20,900 mL/L/day | B32: Y_CH4 x S0_max = 380 x 55 (Federici 2020)
A33: pH : 6.8 to 7.5 | B33: Stable mesophilic range (Borja 2003, Federici 2020)
A34: T : 30 to 42 °C | B34: Full mesophilic range (Borja 2003)
A35: OLR : 1 to 6 g VS/L/day | B35: Stable range for OMSW (Hamdi 1999)
A36: dS/dt : -5.5 to 0 g VS/L/day | B36: VS only decreases; max rate at T=42,S0=55,day0
A37: dM/dt : 0 to 2,000 mL/L/day2 | B37: Methane only increases; max observed 1,916
A38: dpH/dt: -0.09 to 0 pH/day | B38: pH only drops or stable; max drop at S0=55
A40: DATA AUGMENTATION
A41: Base rows | B41: 1,080 (36 runs x 30 daily timesteps)
A42: Replications | B42: 25 noisy copies per row
A43: Noise sigma | B43: 0.05 x 0.333 = 1.67% of each value (Gaussian)
A44: Training rows | B44: 27,000 (shuffled, random seed = 42)
A45: Scaler fitting | B45: StandardScaler fitted on STANDARDISATION_REF (clean data only)
A47: REFERENCES
...

Sheet PHYSICAL_LIMITS
A1: Physical Limits — Anaerobic Digestion of Olive Mill Waste
A2: All limits enforced against RAW_SIMULATION sheet. GREEN = all rows pass | RED = violations found. Click any CHECK cell to see count of violations.
A3: Variable | B3: Min | C3: Max | D3: Units | E3: Justification / Source | F3: RAW_SIMULATION Column | G3: Violations | H3: Total Rows | I3: STATUS
A4: S_gVS_L | B4: 0 | C4: 55 | D4: g VS/L | E4: S>=0 physical; S0_max=55 g/L (Borja 2003) | F4: S_gVS_L | G4: =COUNTIF(RAW_SIMULATION!F3:RAW_SIMULATION!F1082,"<"&B4)+COUNTIF(RAW_SIMULATION!F3:RAW_SIMULATION!F1082,">"&C4) -> 0 | H4: =1080 -> 1080 | I4: =IF(G4=0,"PASS","FAIL") -> PASS
A5: M_mL_L_day | B5: 0 | C5: 20900 | D5: mL CH4/L/day | E5: Y_CH4 x S0_max = 380 x 55 = 20,900 (Federici 2020) | F5: M_mL_L_day | G5: =COUNTIF(RAW_SIMULATION!G3:RAW_SIMULATION!G1082,"<"&B5)+COUNTIF(RAW_SIMULATION!G3:RAW_SIMULATION!G1082,">"&C5) -> 0 | H5: =1080 -> 1080 | I5: =IF(G5=0,"PASS","FAIL") -> PASS
A6: pH | B6: 6.8 | C6: 7.5 | D6: — | E6: Stable mesophilic digestion range (Borja 2003, Federici 2020) | F6: pH | G6: =COUNTIF(RAW_SIMULATION!H3:RAW_SIMULATION!H1082,"<"&B6)+COUNTIF(RAW_SIMULATION!H3:RAW_SIMULATION!H1082,">"&C6) -> 0 | H6: =1080 -> 1080 | I6: =IF(G6=0,"PASS","FAIL") -> PASS
A7: T_C | B7: 30 | C7: 42 | D7: °C | E7: Mesophilic temperature range (Borja 2003) | F7: T_C | G7: =COUNTIF(RAW_SIMULATION!B3:RAW_SIMULATION!B1082,"<"&B7)+COUNTIF(RAW_SIMULATION!B3:RAW_SIMULATION!B1082,">"&C7) -> 0 | H7: =1080 -> 1080 | I7: =IF(G7=0,"PASS","FAIL") -> PASS
A8: OLR | B8: 1 | C8: 6 | D8: g VS/L/day | E8: Stable OLR for OMSW without acidification failure (Hamdi 1999) | F8: OLR_gVS_L_day | G8: =COUNTIF(RAW_SIMULATION!D3:RAW_SIMULATION!D1082,"<"&B8)+COUNTIF(RAW_SIMULATION!D3:RAW_SIMULATION!D1082,">"&C8) -> 0 | H8: =1080 -> 1080 | I8: =IF(G8=0,"PASS","FAIL") -> PASS
A9: dS_dt | B9: -5.5 | C9: 0 | D9: g VS/L/day | E9: VS only decreases (negative); max rate at T=42,S0=55,day0 | F9: dS_dt | G9: =COUNTIF(RAW_SIMULATION!I3:RAW_SIMULATION!I1082,"<"&B9)+COUNTIF(RAW_SIMULATION!I3:RAW_SIMULATION!I1082,">"&C9) -> 0 | H9: =1080 -> 1080 | I9: =IF(G9=0,"PASS","FAIL") -> PASS
A10: dM_dt | B10: 0 | C10: 2000 | D10: mL/L/day2 | E10: Methane rate only increases (positive); max observed 1,916 | F10: dM_dt | G10: =COUNTIF(RAW_SIMULATION!J3:RAW_SIMULATION!J1082,"<"&B10)+COUNTIF(RAW_SIMULATION!J3:RAW_SIMULATION!J1082,">"&C10) -> 0 | H10: =1080 -> 1080 | I10: =IF(G10=0,"PASS","FAIL") -> PASS
A11: dpH_dt | B11: -0.09 | C11: 0 | D11: pH/day | E11: pH only drops or stays flat; max observed -0.086 | F11: dpH_dt | G11: =COUNTIF(RAW_SIMULATION!K3:RAW_SIMULATION!K1082,"<"&B11)+COUNTIF(RAW_SIMULATION!K3:RAW_SIMULATION!K1082,">"&C11) -> 0 | H11: =1080 -> 1080 | I11: =IF(G11=0,"PASS","FAIL") -> PASS

Sheet RAW_SIMULATION
A1: run_id | B1: T_C | C1: S0_gVS_L | D1: OLR_gVS_L_day | E1: day | F1: S_gVS_L | G1: M_mL_L_day | H1: pH | I1: dS_dt | J1: dM_dt | K1: dpH_dt
A2: Run ID | B2: Temp (°C) | C2: Initial VS (g/L) | D2: OLR (g/L/day) | E2: Day (0–29) | F2: Vol. Solids (g/L) | G2: Methane (mL/L/day) | H2: pH | I2: dS/dt | J2: dM/dt | K2: dpH/dt
A3: 1 | B3: 30 | C3: 15 | D3: 1 | E3: 0 | F3: 15 | G3: 0 | H3: 7.4 | I3: -1.388167 | J3: 527.50352 | K3: -0.021726
A4: 1 | B4: 30 | C4: 15 | D4: 1 | E4: 1 | F4: 13.6118 | G4: 527.5035 | H4: 7.3783 | I4: -1.252597 | J4: 475.98705 | K4: -0.018729
A5: 1 | B5: 30 | C5: 15 | D5: 1 | E5: 2 | F5: 12.3592 | G5: 1003.4906 | H5: 7.3595 | I5: -1.131612 | J5: 430.01249 | K5: -0.016185
A6: 1 | B6: 30 | C6: 15 | D6: 1 | E6: 3 | F6: 11.2276 | G6: 1433.5031 | H6: 7.3434 | I6: -1.023404 | J6: 388.89347 | K6: -0.01401
A7: 1 | B7: 30 | C7: 15 | D7: 1 | E7: 4 | F7: 10.2042 | G7: 1822.3965 | H7: 7.3293 | I7: -0.926429 | J7: 352.04306 | K7: -0.01214
A8: 1 | B8: 30 | C8: 15 | D8: 1 | E8: 5 | F8: 9.2778 | G8: 2174.4396 | H8: 7.3172 | I8: -0.839362 | J8: 318.95745 | K8: -0.010522
A9: 1 | B9: 30 | C9: 15 | D9: 1 | E9: 6 | F9: 8.4384 | G9: 2493.397 | H9: 7.3067 | I9: -0.761059 | J9: 289.20243 | K9: -0.009116
A10: 1 | B10: 30 | C10: 15 | D10: 1 | E10: 7 | F10: 7.6774 | G10: 2782.5995 | H10: 7.2976 | I10: -0.690532 | J10: 262.40228 | K10: -0.007888
A11: 1 | B11: 30 | C11: 15 | D11: 1 | E11: 8 | F11: 6.9868 | G11: 3045.0018 | H11: 7.2897 | I11: -0.626923 | J11: 238.23062 | K11: -0.00681
A12: 1 | B12: 30 | C12: 15 | D12: 1 | E12: 9 | F12: 6.3599 | G12: 3283.2324 | H12: 7.2829 | I12: -0.569481 | J12: 216.4028 | K12: -0.005861
A13: 1 | B13: 30 | C13: 15 | D13: 1 | E13: 10 | F13: 5.7904 | G13: 3499.6352 | H13: 7.277 | I13: -0.517552 | J13: 196.6697 | K13: -0.005021
A14: 1 | B14: 30 | C14: 15 | D14: 1 | E14: 11 | F14: 5.2729 | G14: 3696.3049 | H14: 7.272 | I14: -0.470559 | J14: 178.8125 | K14: -0.004276
... A1082: 36 | B1082: 42 | C1082: 55 | D1082: 6 | E1082: 29 | F1082: 19.9791 | G1082: 13307.924 | H1082: 6.8374 | I1082: -0.637949 | J1082: 242.42081 | K1082: -0.00193

Sheet STANDARDISATION_REF
A1: S_gVS_L | B1: M_mL_L_day | C1: pH | D1: T_C | E1: OLR_gVS_L_day | F1: dS_dt | G1: dM_dt | H1: dpH_dt
A2: Vol. Solids (g/L) | B2: Methane (mL/L/day) | C2: pH | D2: Temperature (°C) | E2: OLR (g/L/day) | F2: dS/dt | G2: dM/dt | H2: dpH/dt
A3: USE THIS SHEET to fit StandardScaler — clean data only, no noise augmentation. scaler.fit(data_ref) where data_ref = rows 4 onwards, all 8 columns.
A4: 15 | B4: 0 | C4: 7.4 | D4: 30 | E4: 1 | F4: -1.388167 | G4: 527.50352 | H4: -0.021726
A5: 13.6118 | B5: 527.5035 | C5: 7.3783 | D5: 30 | E5: 1 | F5: -1.252597 | G5: 475.98705 | H5: -0.018729
A6: 12.3592 | B6: 1003.4906 | C6: 7.3595 | D6: 30 | E6: 1 | F6: -1.131612 | G6: 430.01249 | H6: -0.016185
A7: 11.2276 | B7: 1433.5031 | C7: 7.3434 | D7: 30 | E7: 1 | F7: -1.023404 | G7: 388.89347 | H7: -0.01401
A8: 10.2042 | B8: 1822.3965 | C8: 7.3293 | D8: 30 | E8: 1 | F8: -0.926429 | G8: 352.04306 | H8: -0.01214
A9: 9.2778 | B9: 2174.4396 | C9: 7.3172 | D9: 30 | E9: 1 | F9: -0.839362 | G9: 318.95745 | H9: -0.010522
A10: 8.4384 | B10: 2493.397 | C10: 7.3067 | D10: 30 | E10: 1 | F10: -0.761059 | G10: 289.20243 | H10: -0.009116
A11: 7.6774 | B11: 2782.5995 | C11: 7.2976 | D11: 30 | E11: 1 | F11: -0.690532 | G11: 262.40228 | H11: -0.007888
A12: 6.9868 | B12: 3045.0018 | C12: 7.2897 | D12: 30 | E12: 1 | F12: -0.626923 | G12: 238.23062 | H12: -0.00681
A13: 6.3599 | B13: 3283.2324 | C13: 7.2829 | D13: 30 | E13: 1 | F13: -0.569481 | G13: 216.4028 | H13: -0.005861
A14: 5.7904 | B14: 3499.6352 | C14: 7.277 | D14: 30 | E14: 1 | F14: -0.517552 | G14: 196.6697 | H14: -0.005021
A15: 5.2729 | B15: 3696.3049 | C15: 7.272 | D15: 30 | E15: 1 | F15: -0.470559 | G15: 178.8125 | H15: -0.004276
... A1083: 19.9791 | B1083: 13307.924 | C1083: 6.8374 | D1083: 42 | E1083: 6 | F1083: -0.637949 | G1083: 242.42081 | H1083: -0.00193

Sheet PREPARED_TRAINING
A1: S_gVS_L | B1: M_mL_L_day | C1: pH | D1: T_C | E1: OLR_gVS_L_day | F1: dS_dt | G1: dM_dt | H1: dpH_dt
A2: Vol. Solids (g/L) | B2: Methane (mL/L/day) | C2: pH | D2: Temperature (°C) | E2: OLR (g/L/day) | F2: dS/dt | G2: dM/dt | H2: dpH/dt
A3: USE THIS SHEET for neural network training. Columns 1-5 = inputs (x_train), columns 6-8 = targets (y_train). 27,000 rows shuffled with random seed 42. Noise sigma = 1.67%.
A4: 2.933288 | B4: 4611.7715 | C4: 7.124296 | D4: 29.830834 | E4: 3.07325 | F4: -0.273846 | G4: 99.080938 | H4: -0.001191
A5: 17.319054 | B5: 6634.3386 | C5: 7.175688 | D5: 38.254249 | E5: 0.996763 | F5: -0.857126 | G5: 326.56889 | H5: -0.010865
A6: 7.076621 | B6: 10579.343 | C6: 7.134322 | D6: 35.27674 | E6: 3.073583 | F6: -0.393789 | G6: 151.91122 | H6: -0.00266
A7: 21.42526 | B7: 5467.0546 | C7: 7.025224 | D7: 33.902185 | E7: 3.073853 | F7: -1.270328 | G7: 475.88322 | H7: -0.01737
A8: 2.44375 | B8: 4794.9148 | C8: 7.0629 | D8: 30.075932 | E8: 5.95532 | F8: -0.21754 | G8: 83.825911 | H8: -0.000519
A9: 19.588559 | B9: 13359.879 | C9: 6.93558 | D9: 37.928974 | E9: 3.107449 | F9: -0.849236 | G9: 317.98047 | H9: -0.0037
A10: 6.021374 | B10: 3390.1959 | C10: 7.242263 | D10: 35.277998 | E10: 0.994846 | F10: -0.380185 | G10: 138.55413 | H10: -0.004828
A11: 4.520684 | B11: 11500.498 | C11: 6.939344 | D11: 30.866122 | E11: 2.949729 | F11: -0.366328 | G11: 142.87131 | H11: -0.001784
A12: 13.424711 | B12: 524.68079 | C12: 7.429029 | D12: 29.718419 | E12: 0.986309 | F12: -1.247514 | G12: 477.92845 | H12: -0.018888
A13: 4.226314 | B13: 4087.4647 | C13: 7.100241 | D13: 34.785577 | E13: 3.022484 | F13: -0.269609 | G13: 101.20701 | H13: -0.00267
A14: 10.395507 | B14: 1781.8331 | C14: 7.128848 | D14: 43.206723 | E14: 3.091912 | F14: -0.408245 | G14: 148.95169 | H14: -0.01097
A15: 11.794852 | B15: 8911.1895 | C15: 7.121761 | D15: 30.341006 | E15: 6.046662 | F15: -1.023028 | G15: 377.54826 | H15: -0.008135
... A27003: 29.414855 | B27003: 9878.8156 | C27003: 6.957275 | D27003: 29.553794 | E27003: 3.046932 | F27003: -2.455923 | G27003: 916.24042 | H27003: -0.020142
